<?xml version="1.0" ?>
<!-- =================================================================================== -->
<!-- |    This document was autogenerated by xacro from pap_arm.xacro                  | -->
<!-- |    EDITING THIS FILE BY HAND IS NOT RECOMMENDED                                 | -->
<!-- =================================================================================== -->
<robot name="pap_arm">
  <material name="green">
    <color rgba="0 0.5 0 1"/>
  </material>
  <material name="red">
    <color rgba="0.5 0 0 1"/>
  </material>
  <material name="orange">
    <color rgba="1 0.6 0 1"/>
  </material>
  <material name="grey">
    <color rgba="0.5 0.5 0.5 1"/>
  </material>
  <material name="blue">
    <color rgba="0 0 0.5 1"/>
  </material>
  <!-- LINKS -->
  <!--     <link name="base_footprint"></link> -->
  <link name="base_link">
    <visual>
      <geometry>
        <box size="0.4 0.4 0.03"/>
      </geometry>
      <origin rpy="0 0 0" xyz="0 0 0"/>
      <material name="grey"/>
    </visual>
    <!--         <xacro:box_inertia m="3.0" x="${base_length}" y="${base_width}" z="${base_height}" o_xyz="0 0 0" o_rpy="0 0 0"/> -->
    <collision>
      <geometry>
        <box size="0.4 0.4 0.03"/>
      </geometry>
      <origin rpy="0 0 0" xyz="0 0 0"/>
    </collision>
  </link>
  <link name="link1">
    <visual>
      <geometry>
        <cylinder length="0.05" radius="0.04"/>
      </geometry>
      <origin rpy="0 0 0" xyz="0 0 0.025"/>
      <material name="grey"/>
    </visual>
    <!--             <xacro:box_inertia m="${mass}" x="${radius*2.0}" y="${radius*2.0}" z="${length}" o_xyz="0 0 ${length/2}" o_rpy="0 0 0"/> -->
    <collision>
      <geometry>
        <box size="0.08 0.08 0.05"/>
      </geometry>
      <origin rpy="0 0 0" xyz="0 0 0.025"/>
    </collision>
  </link>
  <link name="link2">
    <visual>
      <geometry>
        <cylinder length="0.3" radius="0.04"/>
      </geometry>
      <origin rpy="0 0 0" xyz="0 0 0.15"/>
      <material name="blue"/>
    </visual>
    <!--             <xacro:box_inertia m="${mass}" x="${radius*2.0}" y="${radius*2.0}" z="${length}" o_xyz="0 0 ${length/2}" o_rpy="0 0 0"/> -->
    <collision>
      <geometry>
        <box size="0.08 0.08 0.3"/>
      </geometry>
      <origin rpy="0 0 0" xyz="0 0 0.15"/>
    </collision>
  </link>
  <link name="link3">
    <visual>
      <geometry>
        <cylinder length="0.25" radius="0.035"/>
      </geometry>
      <origin rpy="0 0 0" xyz="0 0 0.125"/>
      <material name="grey"/>
    </visual>
    <!--             <xacro:box_inertia m="${mass}" x="${radius*2.0}" y="${radius*2.0}" z="${length}" o_xyz="0 0 ${length/2}" o_rpy="0 0 0"/> -->
    <collision>
      <geometry>
        <box size="0.07 0.07 0.25"/>
      </geometry>
      <origin rpy="0 0 0" xyz="0 0 0.125"/>
    </collision>
  </link>
  <link name="link4">
    <visual>
      <geometry>
        <cylinder length="0.05" radius="0.03"/>
      </geometry>
      <origin rpy="0 0 0" xyz="0 0 0.025"/>
      <material name="blue"/>
    </visual>
    <!--             <xacro:box_inertia m="${mass}" x="${radius*2.0}" y="${radius*2.0}" z="${length}" o_xyz="0 0 ${length/2}" o_rpy="0 0 0"/> -->
    <collision>
      <geometry>
        <box size="0.06 0.06 0.05"/>
      </geometry>
      <origin rpy="0 0 0" xyz="0 0 0.025"/>
    </collision>
  </link>
  <link name="link5">
    <visual>
      <geometry>
        <cylinder length="0.05" radius="0.03"/>
      </geometry>
      <origin rpy="0 0 0" xyz="0 0 0.025"/>
      <material name="blue"/>
    </visual>
    <!--             <xacro:box_inertia m="${mass}" x="${radius*2.0}" y="${radius*2.0}" z="${length}" o_xyz="0 0 ${length/2}" o_rpy="0 0 0"/> -->
    <collision>
      <geometry>
        <box size="0.06 0.06 0.05"/>
      </geometry>
      <origin rpy="0 0 0" xyz="0 0 0.025"/>
    </collision>
  </link>
  <link name="link6">
    <visual>
      <geometry>
        <cylinder length="0.05" radius="0.03"/>
      </geometry>
      <origin rpy="0 0 0" xyz="0 0 0.025"/>
      <material name="blue"/>
    </visual>
    <!--             <xacro:box_inertia m="${mass}" x="${radius*2.0}" y="${radius*2.0}" z="${length}" o_xyz="0 0 ${length/2}" o_rpy="0 0 0"/> -->
    <collision>
      <geometry>
        <box size="0.06 0.06 0.05"/>
      </geometry>
      <origin rpy="0 0 0" xyz="0 0 0.025"/>
    </collision>
  </link>
  <link name="end_effector">
        
    </link>
  <!-- JOINTS -->
  <!-- <joint name="base_footprint_base" type="fixed">
        <parent link="base_footprint"/>
        <child link="base_link"/>
        <origin xyz="0 0 ${base_height/2.0}" rpy="0 0 0"/>
    </joint> -->
  <joint name="base_link_link1" type="revolute">
    <parent link="base_link"/>
    <child link="link1"/>
    <origin rpy="0 0 0" xyz="0 0 0.015"/>
    <axis xyz="0 0 1"/>
    <limit effort="10.0" lower="-3.14" upper="3.14" velocity="1.0"/>
  </joint>
  <joint name="link1_link2" type="revolute">
    <parent link="link1"/>
    <child link="link2"/>
    <origin rpy="0 0 0" xyz="0 0 0.05"/>
    <axis xyz="0 1 0"/>
    <limit effort="10.0" lower="-1.57" upper="1.57" velocity="1.0"/>
  </joint>
  <joint name="link2_link3" type="revolute">
    <parent link="link2"/>
    <child link="link3"/>
    <origin rpy="0 0 0" xyz="0 0 0.3"/>
    <axis xyz="0 1 0"/>
    <limit effort="10.0" lower="-2.62" upper="2.62" velocity="1.0"/>
  </joint>
  <joint name="link3_link4" type="revolute">
    <parent link="link3"/>
    <child link="link4"/>
    <origin rpy="0 0 0" xyz="0 0 0.25"/>
    <axis xyz="0 0 1"/>
    <limit effort="10.0" lower="-3.14" upper="3.14" velocity="1.0"/>
  </joint>
  <joint name="link4_link5" type="revolute">
    <parent link="link4"/>
    <child link="link5"/>
    <origin rpy="0 0 0" xyz="0 0 0.05"/>
    <axis xyz="0 1 0"/>
    <limit effort="10.0" lower="-2.35" upper="2.35" velocity="1.0"/>
  </joint>
  <joint name="link5_link6" type="revolute">
    <parent link="link5"/>
    <child link="link6"/>
    <origin rpy="0 0 0" xyz="0 0 0.05"/>
    <axis xyz="1 0 0"/>
    <limit effort="10.0" lower="-3.14" upper="3.14" velocity="1.0"/>
  </joint>
  <joint name="link6_end_effector" type="continuous">
    <parent link="link6"/>
    <child link="end_effector"/>
    <origin rpy="0 0 0" xyz="0 0 0.05"/>
    <axis xyz="0 0 1"/>
  </joint>
  <gazebo reference="base_link">
    <mu1 value="0.2"/>
    <mu2 value="0.2"/>
  </gazebo>
  <gazebo>
    <plugin filename="gz-sim-joint-position-controller-system" name="gz::sim::systems::JointPositionController">
      <joint_name>base_link_link1</joint_name>
      <p_gain>5.0</p_gain>
    </plugin>
  </gazebo>
  <gazebo>
    <plugin filename="gz-sim-joint-position-controller-system" name="gz::sim::systems::JointPositionController">
      <joint_name>link1_link2</joint_name>
      <p_gain>3.0</p_gain>
    </plugin>
  </gazebo>
  <gazebo>
    <plugin filename="gz-sim-joint-position-controller-system" name="gz::sim::systems::JointPositionController">
      <joint_name>link2_link3</joint_name>
      <p_gain>3.0</p_gain>
    </plugin>
  </gazebo>
  <gazebo>
    <plugin filename="gz-sim-joint-position-controller-system" name="gz::sim::systems::JointPositionController">
      <joint_name>link3_link4</joint_name>
      <p_gain>3.0</p_gain>
    </plugin>
  </gazebo>
  <gazebo>
    <plugin filename="gz-sim-joint-position-controller-system" name="gz::sim::systems::JointPositionController">
      <joint_name>link4_link5</joint_name>
      <p_gain>3.0</p_gain>
    </plugin>
  </gazebo>
  <gazebo>
    <plugin filename="gz-sim-joint-position-controller-system" name="gz::sim::systems::JointPositionController">
      <joint_name>link5_link6</joint_name>
      <p_gain>3.0</p_gain>
    </plugin>
  </gazebo>
  <gazebo>
    <plugin filename="gz-sim-joint-state-publisher-system" name="gz::sim::systems::JointStatePublisher">
      <joint_name>base_link_link1</joint_name>
      <joint_name>link1_link2</joint_name>
      <joint_name>link2_link3</joint_name>
      <joint_name>link3_link4</joint_name>
      <joint_name>link4_link5</joint_name>
      <joint_name>link5_link6</joint_name>
    </plugin>
  </gazebo>
  <link name="claw_base">
    <!--         <xacro:box_inertia m="3.0" x="${2*claw_base_radius}"  y="${2*claw_base_radius}"  z="${claw_base_length}"  o_xyz="0 0 0" o_rpy="0 0 0"/> -->
    <visual>
      <origin rpy="0.0 0.0 0.0" xyz="0.0 0.0 0.0"/>
      <geometry>
        <cylinder length="0.02" radius="0.06"/>
      </geometry>
      <material name="grey"/>
    </visual>
    <collision>
      <origin rpy="0.0 0.0 0.0" xyz="0.0 0.0 0.0"/>
      <geometry>
        <box size="0.12 0.12 0.02"/>
      </geometry>
    </collision>
  </link>
  <!-- FINGER LINK 1 -->
  <link name="one_claw_finger">
    <visual>
      <origin rpy="0.0 0.0 0.0" xyz="0 0.0 0.02"/>
      <geometry>
        <box size="0.01 0.02 0.04"/>
      </geometry>
      <material name="grey"/>
    </visual>
    <collision>
      <origin rpy="0.0 0.0 0.0" xyz="0 0.0 0.02"/>
      <geometry>
        <box size="0.01 0.02 0.04"/>
      </geometry>
    </collision>
    <!--             <xacro:box_inertia m="0.2" x="${claw_finger_length}" y="${claw_finger_width}" z="${claw_finger_height}" o_xyz="0 0 ${claw_finger_height/2.0}" o_rpy="0 0 0"/> -->
  </link>
  <!-- FINGER LINK 2 -->
  <link name="gripper_claw_one">
    <visual>
      <origin rpy="0.0 0.0 0.0" xyz="0.0 0.0 0.02"/>
      <geometry>
        <box size="0.01 0.02 0.04"/>
      </geometry>
      <material name="grey"/>
    </visual>
    <collision>
      <origin rpy="0.0 0.0 0.0" xyz="0.0 0.0 0.02"/>
      <geometry>
        <box size="0.01 0.02 0.04"/>
      </geometry>
    </collision>
    <!--             <xacro:box_inertia m="0.1" x="${claw_finger_length}" y="${claw_finger_width}" z="${claw_finger_height}" o_xyz="0 0 ${claw_finger_height/2.0}" o_rpy="0 0 0"/> -->
  </link>
  <joint name="finger_claw_one" type="fixed">
    <origin rpy="0 0.5 0" xyz="0 0 0.044000000000000004"/>
    <parent link="one_claw_finger"/>
    <child link="gripper_claw_one"/>
  </joint>
  <!-- FINGER LINK 1 -->
  <link name="two_claw_finger">
    <visual>
      <origin rpy="0.0 0.0 0.0" xyz="0 0.0 0.02"/>
      <geometry>
        <box size="0.01 0.02 0.04"/>
      </geometry>
      <material name="grey"/>
    </visual>
    <collision>
      <origin rpy="0.0 0.0 0.0" xyz="0 0.0 0.02"/>
      <geometry>
        <box size="0.01 0.02 0.04"/>
      </geometry>
    </collision>
    <!--             <xacro:box_inertia m="0.2" x="${claw_finger_length}" y="${claw_finger_width}" z="${claw_finger_height}" o_xyz="0 0 ${claw_finger_height/2.0}" o_rpy="0 0 0"/> -->
  </link>
  <!-- FINGER LINK 2 -->
  <link name="gripper_claw_two">
    <visual>
      <origin rpy="0.0 0.0 0.0" xyz="0.0 0.0 0.02"/>
      <geometry>
        <box size="0.01 0.02 0.04"/>
      </geometry>
      <material name="grey"/>
    </visual>
    <collision>
      <origin rpy="0.0 0.0 0.0" xyz="0.0 0.0 0.02"/>
      <geometry>
        <box size="0.01 0.02 0.04"/>
      </geometry>
    </collision>
    <!--             <xacro:box_inertia m="0.1" x="${claw_finger_length}" y="${claw_finger_width}" z="${claw_finger_height}" o_xyz="0 0 ${claw_finger_height/2.0}" o_rpy="0 0 0"/> -->
  </link>
  <joint name="finger_claw_two" type="fixed">
    <origin rpy="0 0.5 0" xyz="0 0 0.044000000000000004"/>
    <parent link="two_claw_finger"/>
    <child link="gripper_claw_two"/>
  </joint>
  <!-- FINGER LINK 1 -->
  <link name="three_claw_finger">
    <visual>
      <origin rpy="0.0 0.0 0.0" xyz="0 0.0 0.02"/>
      <geometry>
        <box size="0.01 0.02 0.04"/>
      </geometry>
      <material name="grey"/>
    </visual>
    <collision>
      <origin rpy="0.0 0.0 0.0" xyz="0 0.0 0.02"/>
      <geometry>
        <box size="0.01 0.02 0.04"/>
      </geometry>
    </collision>
    <!--             <xacro:box_inertia m="0.2" x="${claw_finger_length}" y="${claw_finger_width}" z="${claw_finger_height}" o_xyz="0 0 ${claw_finger_height/2.0}" o_rpy="0 0 0"/> -->
  </link>
  <!-- FINGER LINK 2 -->
  <link name="gripper_claw_three">
    <visual>
      <origin rpy="0.0 0.0 0.0" xyz="0.0 0.0 0.02"/>
      <geometry>
        <box size="0.01 0.02 0.04"/>
      </geometry>
      <material name="grey"/>
    </visual>
    <collision>
      <origin rpy="0.0 0.0 0.0" xyz="0.0 0.0 0.02"/>
      <geometry>
        <box size="0.01 0.02 0.04"/>
      </geometry>
    </collision>
    <!--             <xacro:box_inertia m="0.1" x="${claw_finger_length}" y="${claw_finger_width}" z="${claw_finger_height}" o_xyz="0 0 ${claw_finger_height/2.0}" o_rpy="0 0 0"/> -->
  </link>
  <joint name="finger_claw_three" type="fixed">
    <origin rpy="0 0.5 0" xyz="0 0 0.044000000000000004"/>
    <parent link="three_claw_finger"/>
    <child link="gripper_claw_three"/>
  </joint>
  <joint name="claw_base_finger_one" type="revolute">
    <origin rpy="0.0 -0.5  0.0" xyz="-0.05 0.0 0.013333333333333334"/>
    <parent link="claw_base"/>
    <child link="one_claw_finger"/>
    <axis xyz="0.0 1.0 0.0"/>
    <limit effort="10.0" lower="0" upper="0.75" velocity="10.0"/>
  </joint>
  <joint name="claw_base_finger_two" type="revolute">
    <origin rpy="0.0  -0.5 -2.09" xyz="0.025 0.043300000000000005 0.013333333333333334"/>
    <parent link="claw_base"/>
    <child link="two_claw_finger"/>
    <axis xyz="0.0 1.0 0.0"/>
    <limit effort="10.0" lower="0.0" upper="1.2" velocity="10.0"/>
    <mimic joint="claw_base_finger_one" multiplier="1.0"/>
  </joint>
  <joint name="claw_base_finger_three" type="revolute">
    <origin rpy="0.0 -0.5 2.09" xyz="0.025 -0.043300000000000005 0.013333333333333334"/>
    <parent link="claw_base"/>
    <child link="three_claw_finger"/>
    <axis xyz="0.0 1.0 0.0"/>
    <limit effort="10.0" lower="0.0" upper="1.2" velocity="10.0"/>
    <mimic joint="claw_base_finger_one" multiplier="1.0"/>
  </joint>
  <ros2_control name="Arm" type="system">
    <hardware>
      <!-- By default, set up controllers for simulation. This won't work on real hardware -->
      <plugin>mock_components/GenericSystem</plugin>
    </hardware>
    <joint name="base_link_link1">
      <command_interface name="position"/>
      <state_interface name="position">
        <param name="initial_value">0</param>
      </state_interface>
    </joint>
    <joint name="link1_link2">
      <command_interface name="position"/>
      <state_interface name="position">
        <param name="initial_value">0</param>
      </state_interface>
    </joint>
    <joint name="link2_link3">
      <command_interface name="position"/>
      <state_interface name="position">
        <param name="initial_value">0</param>
      </state_interface>
    </joint>
    <joint name="link3_link4">
      <command_interface name="position"/>
      <state_interface name="position">
        <param name="initial_value">0</param>
      </state_interface>
    </joint>
    <joint name="link4_link5">
      <command_interface name="position"/>
      <state_interface name="position">
        <param name="initial_value">0</param>
      </state_interface>
    </joint>
    <joint name="link5_link6">
      <command_interface name="position"/>
      <state_interface name="position">
        <param name="initial_value">0</param>
      </state_interface>
    </joint>
    <joint name="link6_end_effector">
      <command_interface name="position"/>
      <state_interface name="position">
        <param name="initial_value">0</param>
      </state_interface>
    </joint>
    <joint name="claw_base_finger_one">
      <command_interface name="position"/>
      <state_interface name="position">
        <param name="initial_value">0</param>
      </state_interface>
    </joint>
  </ros2_control>
  <!-- <joint name="end_effector_gripper" type="fixed">
        <origin xyz="0.0 0.0 ${gripper_base_height/2.0}" rpy="0.0 0.0 0.0"/>
        <parent link="end_effector"/>
        <child link="gripper_base"/>
        
    </joint> -->
  <joint name="end_effector_gripper" type="fixed">
    <origin rpy="0.0 0.0 0.0" xyz="0.0 0.0 0.01"/>
    <parent link="end_effector"/>
    <child link="claw_base"/>
  </joint>
</robot>
